Workbook
Name OcupacionReal: 'Seguimiento Diario'!$E$6:$E$33
Name TarifaReal: 'Seguimiento Diario'!$G$6:$G$33
Name IngresosDiarios: 'Seguimiento Diario'!$H$6:$H$33
Name MetaMensual: 'Seguimiento Diario'!$D$4
Name DiasCapturados: COUNTA('Seguimiento Diario'!$E$6:$E$33)
Name ProyeccionMensual: 'Seguimiento Diario'!$Q$7

Sheet 📊 Inicio
A1: PANEL DE CONTROL - HOTEL INH3RI
A2: 85 Habitaciones | Sistema de Seguimiento
A4: NAVEGACIÓN RÁPIDA
A6: =HYPERLINK("#'Hoja1'!A1", "→ Reporte Histórico") | B6: Datos mensuales de ocupación e ingresos
A7: =HYPERLINK("#'Dashboard KPIs'!A1", "→ Dashboard KPIs") | B7: Indicadores clave de rendimiento
A8: =HYPERLINK("#'Seguimiento Diario'!A1", "→ Seguimiento Diario") | B8: Registro día a día
A9: =HYPERLINK("#'Análisis y Recomendaciones'!A1", "→ Análisis") | B9: 20 puntos de mejora
A10: =HYPERLINK("#'Gráficos'!A1", "→ Gráficos") | B10: Visualizaciones de datos
A12: INSTRUCCIONES DE USO
A13: 1. CAMBIAR DE MES: | B13: Solo cambia el mes en celda S3 de "Seguimiento Diario"
A14: 2. LOS DÍAS SE AJUSTAN: | B14: Automáticamente muestra 28, 29, 30 o 31 días
A15: 3. LIMPIAR DATOS: | B15: Borra E6:E36 (ocupación) y G6:G36 (tarifas)
A16: 4. GUARDAR HISTÓRICO: | B16: Antes de limpiar, copia totales a hoja Histórico
A18: Contraseña hojas protegidas: hotel2026
A20: EXPORTAR A PDF | C20: [ EXPORTAR PDF ]
A21: Para agregar el botón de exportación: | C21: (Requiere macro - ver instrucciones)
A22: 1. Guarda este archivo como .xlsm (Libro habilitado para macros)
A23: 2. Presiona Alt+F11 para abrir el editor VBA
A24: 3. Inserta → Módulo
A25: 4. Pega el código que está en la hoja "Macro_PDF"
A26: 5. Cierra el editor y guarda
A27: 6. Usa Alt+F8 → ExportarPDF para ejecutar

Sheet 📅 Calendario
A1: CALENDARIO DE OCUPACIÓN
A2: ='Seguimiento Diario'!S3&" "&'Seguimiento Diario'!S4 | I2: =WEEKDAY(DATE('Seguimiento Diario'!S4,VALUE(LEFT('Seguimiento Diario'!S3,FIND("-",'Seguimiento Diario'!S3)-1)),1),2)
I3: ='Seguimiento Diario'!S6
A4: LUN | B4: MAR | C4: MIÉ | D4: JUE | E4: VIE | F4: SÁB | G4: DOM
A5: =IF(AND(0*7+1-$I$2+1>=1,0*7+1-$I$2+1<=$I$3),0*7+1-$I$2+1,"") | B5: =IF(AND(0*7+2-$I$2+1>=1,0*7+2-$I$2+1<=$I$3),0*7+2-$I$2+1,"") | C5: =IF(AND(0*7+3-$I$2+1>=1,0*7+3-$I$2+1<=$I$3),0*7+3-$I$2+1,"") | D5: =IF(AND(0*7+4-$I$2+1>=1,0*7+4-$I$2+1<=$I$3),0*7+4-$I$2+1,"") | E5: =IF(AND(0*7+5-$I$2+1>=1,0*7+5-$I$2+1<=$I$3),0*7+5-$I$2+1,"") | F5: =IF(AND(0*7+6-$I$2+1>=1,0*7+6-$I$2+1<=$I$3),0*7+6-$I$2+1,"") | G5: =IF(AND(0*7+7-$I$2+1>=1,0*7+7-$I$2+1<=$I$3),0*7+7-$I$2+1,"")
A6: =IF(A5="","",IFERROR(INDEX('Seguimiento Diario'!$E$6:$E$36,A5)&"%","-")) | B6: =IF(B5="","",IFERROR(INDEX('Seguimiento Diario'!$E$6:$E$36,B5)&"%","-")) | C6: =IF(C5="","",IFERROR(INDEX('Seguimiento Diario'!$E$6:$E$36,C5)&"%","-")) | D6: =IF(D5="","",IFERROR(INDEX('Seguimiento Diario'!$E$6:$E$36,D5)&"%","-")) | E6: =IF(E5="","",IFERROR(INDEX('Seguimiento Diario'!$E$6:$E$36,E5)&"%","-")) | F6: =IF(F5="","",IFERROR(INDEX('Seguimiento Diario'!$E$6:$E$36,F5)&"%","-")) | G6: =IF(G5="","",IFERROR(INDEX('Seguimiento Diario'!$E$6:$E$36,G5)&"%","-"))
A7: =IF(A5="","",IFERROR("$"&TEXT(INDEX('Seguimiento Diario'!$H$6:$H$36,A5),"#,##0"),"-")) | B7: =IF(B5="","",IFERROR("$"&TEXT(INDEX('Seguimiento Diario'!$H$6:$H$36,B5),"#,##0"),"-")) | C7: =IF(C5="","",IFERROR("$"&TEXT(INDEX('Seguimiento Diario'!$H$6:$H$36,C5),"#,##0"),"-")) | D7: =IF(D5="","",IFERROR("$"&TEXT(INDEX('Seguimiento Diario'!$H$6:$H$36,D5),"#,##0"),"-")) | E7: =IF(E5="","",IFERROR("$"&TEXT(INDEX('Seguimiento Diario'!$H$6:$H$36,E5),"#,##0"),"-")) | F7: =IF(F5="","",IFERROR("$"&TEXT(INDEX('Seguimiento Diario'!$H$6:$H$36,F5),"#,##0"),"-")) | G7: =IF(G5="","",IFERROR("$"&TEXT(INDEX('Seguimiento Diario'!$H$6:$H$36,G5),"#,##0"),"-"))
A8: =IF(AND(1*7+1-$I$2+1>=1,1*7+1-$I$2+1<=$I$3),1*7+1-$I$2+1,"") | B8: =IF(AND(1*7+2-$I$2+1>=1,1*7+2-$I$2+1<=$I$3),1*7+2-$I$2+1,"") | C8: =IF(AND(1*7+3-$I$2+1>=1,1*7+3-$I$2+1<=$I$3),1*7+3-$I$2+1,"") | D8: =IF(AND(1*7+4-$I$2+1>=1,1*7+4-$I$2+1<=$I$3),1*7+4-$I$2+1,"") | E8: =IF(AND(1*7+5-$I$2+1>=1,1*7+5-$I$2+1<=$I$3),1*7+5-$I$2+1,"") | F8: =IF(AND(1*7+6-$I$2+1>=1,1*7+6-$I$2+1<=$I$3),1*7+6-$I$2+1,"") | G8: =IF(AND(1*7+7-$I$2+1>=1,1*7+7-$I$2+1<=$I$3),1*7+7-$I$2+1,"")
A9: =IF(A8="","",IFERROR(INDEX('Seguimiento Diario'!$E$6:$E$36,A8)&"%","-")) | B9: =IF(B8="","",IFERROR(INDEX('Seguimiento Diario'!$E$6:$E$36,B8)&"%","-")) | C9: =IF(C8="","",IFERROR(INDEX('Seguimiento Diario'!$E$6:$E$36,C8)&"%","-")) | D9: =IF(D8="","",IFERROR(INDEX('Seguimiento Diario'!$E$6:$E$36,D8)&"%","-")) | E9: =IF(E8="","",IFERROR(INDEX('Seguimiento Diario'!$E$6:$E$36,E8)&"%","-")) | F9: =IF(F8="","",IFERROR(INDEX('Seguimiento Diario'!$E$6:$E$36,F8)&"%","-")) | G9: =IF(G8="","",IFERROR(INDEX('Seguimiento Diario'!$E$6:$E$36,G8)&"%","-"))
A10: =IF(A8="","",IFERROR("$"&TEXT(INDEX('Seguimiento Diario'!$H$6:$H$36,A8),"#,##0"),"-")) | B10: =IF(B8="","",IFERROR("$"&TEXT(INDEX('Seguimiento Diario'!$H$6:$H$36,B8),"#,##0"),"-")) | C10: =IF(C8="","",IFERROR("$"&TEXT(INDEX('Seguimiento Diario'!$H$6:$H$36,C8),"#,##0"),"-")) | D10: =IF(D8="","",IFERROR("$"&TEXT(INDEX('Seguimiento Diario'!$H$6:$H$36,D8),"#,##0"),"-")) | E10: =IF(E8="","",IFERROR("$"&TEXT(INDEX('Seguimiento Diario'!$H$6:$H$36,E8),"#,##0"),"-")) | F10: =IF(F8="","",IFERROR("$"&TEXT(INDEX('Seguimiento Diario'!$H$6:$H$36,F8),"#,##0"),"-")) | G10: =IF(G8="","",IFERROR("$"&TEXT(INDEX('Seguimiento Diario'!$H$6:$H$36,G8),"#,##0"),"-"))
A11: =IF(AND(2*7+1-$I$2+1>=1,2*7+1-$I$2+1<=$I$3),2*7+1-$I$2+1,"") | B11: =IF(AND(2*7+2-$I$2+1>=1,2*7+2-$I$2+1<=$I$3),2*7+2-$I$2+1,"") | C11: =IF(AND(2*7+3-$I$2+1>=1,2*7+3-$I$2+1<=$I$3),2*7+3-$I$2+1,"") | D11: =IF(AND(2*7+4-$I$2+1>=1,2*7+4-$I$2+1<=$I$3),2*7+4-$I$2+1,"") | E11: =IF(AND(2*7+5-$I$2+1>=1,2*7+5-$I$2+1<=$I$3),2*7+5-$I$2+1,"") | F11: =IF(AND(2*7+6-$I$2+1>=1,2*7+6-$I$2+1<=$I$3),2*7+6-$I$2+1,"") | G11: =IF(AND(2*7+7-$I$2+1>=1,2*7+7-$I$2+1<=$I$3),2*7+7-$I$2+1,"")
A12: =IF(A11="","",IFERROR(INDEX('Seguimiento Diario'!$E$6:$E$36,A11)&"%","-")) | B12: =IF(B11="","",IFERROR(INDEX('Seguimiento Diario'!$E$6:$E$36,B11)&"%","-")) | C12: =IF(C11="","",IFERROR(INDEX('Seguimiento Diario'!$E$6:$E$36,C11)&"%","-")) | D12: =IF(D11="","",IFERROR(INDEX('Seguimiento Diario'!$E$6:$E$36,D11)&"%","-")) | E12: =IF(E11="","",IFERROR(INDEX('Seguimiento Diario'!$E$6:$E$36,E11)&"%","-")) | F12: =IF(F11="","",IFERROR(INDEX('Seguimiento Diario'!$E$6:$E$36,F11)&"%","-")) | G12: =IF(G11="","",IFERROR(INDEX('Seguimiento Diario'!$E$6:$E$36,G11)&"%","-"))
A13: =IF(A11="","",IFERROR("$"&TEXT(INDEX('Seguimiento Diario'!$H$6:$H$36,A11),"#,##0"),"-")) | B13: =IF(B11="","",IFERROR("$"&TEXT(INDEX('Seguimiento Diario'!$H$6:$H$36,B11),"#,##0"),"-")) | C13: =IF(C11="","",IFERROR("$"&TEXT(INDEX('Seguimiento Diario'!$H$6:$H$36,C11),"#,##0"),"-")) | D13: =IF(D11="","",IFERROR("$"&TEXT(INDEX('Seguimiento Diario'!$H$6:$H$36,D11),"#,##0"),"-")) | E13: =IF(E11="","",IFERROR("$"&TEXT(INDEX('Seguimiento Diario'!$H$6:$H$36,E11),"#,##0"),"-")) | F13: =IF(F11="","",IFERROR("$"&TEXT(INDEX('Seguimiento Diario'!$H$6:$H$36,F11),"#,##0"),"-")) | G13: =IF(G11="","",IFERROR("$"&TEXT(INDEX('Seguimiento Diario'!$H$6:$H$36,G11),"#,##0"),"-"))
A14: =IF(AND(3*7+1-$I$2+1>=1,3*7+1-$I$2+1<=$I$3),3*7+1-$I$2+1,"") | B14: =IF(AND(3*7+2-$I$2+1>=1,3*7+2-$I$2+1<=$I$3),3*7+2-$I$2+1,"") | C14: =IF(AND(3*7+3-$I$2+1>=1,3*7+3-$I$2+1<=$I$3),3*7+3-$I$2+1,"") | D14: =IF(AND(3*7+4-$I$2+1>=1,3*7+4-$I$2+1<=$I$3),3*7+4-$I$2+1,"") | E14: =IF(AND(3*7+5-$I$2+1>=1,3*7+5-$I$2+1<=$I$3),3*7+5-$I$2+1,"") | F14: =IF(AND(3*7+6-$I$2+1>=1,3*7+6-$I$2+1<=$I$3),3*7+6-$I$2+1,"") | G14: =IF(AND(3*7+7-$I$2+1>=1,3*7+7-$I$2+1<=$I$3),3*7+7-$I$2+1,"")
A15: =IF(A14="","",IFERROR(INDEX('Seguimiento Diario'!$E$6:$E$36,A14)&"%","-")) | B15: =IF(B14="","",IFERROR(INDEX('Seguimiento Diario'!$E$6:$E$36,B14)&"%","-")) | C15: =IF(C14="","",IFERROR(INDEX('Seguimiento Diario'!$E$6:$E$36,C14)&"%","-")) | D15: =IF(D14="","",IFERROR(INDEX('Seguimiento Diario'!$E$6:$E$36,D14)&"%","-")) | E15: =IF(E14="","",IFERROR(INDEX('Seguimiento Diario'!$E$6:$E$36,E14)&"%","-")) | F15: =IF(F14="","",IFERROR(INDEX('Seguimiento Diario'!$E$6:$E$36,F14)&"%","-")) | G15: =IF(G14="","",IFERROR(INDEX('Seguimiento Diario'!$E$6:$E$36,G14)&"%","-"))
A16: =IF(A14="","",IFERROR("$"&TEXT(INDEX('Seguimiento Diario'!$H$6:$H$36,A14),"#,##0"),"-")) | B16: =IF(B14="","",IFERROR("$"&TEXT(INDEX('Seguimiento Diario'!$H$6:$H$36,B14),"#,##0"),"-")) | C16: =IF(C14="","",IFERROR("$"&TEXT(INDEX('Seguimiento Diario'!$H$6:$H$36,C14),"#,##0"),"-")) | D16: =IF(D14="","",IFERROR("$"&TEXT(INDEX('Seguimiento Diario'!$H$6:$H$36,D14),"#,##0"),"-")) | E16: =IF(E14="","",IFERROR("$"&TEXT(INDEX('Seguimiento Diario'!$H$6:$H$36,E14),"#,##0"),"-")) | F16: =IF(F14="","",IFERROR("$"&TEXT(INDEX('Seguimiento Diario'!$H$6:$H$36,F14),"#,##0"),"-")) | G16: =IF(G14="","",IFERROR("$"&TEXT(INDEX('Seguimiento Diario'!$H$6:$H$36,G14),"#,##0"),"-"))
A17: =IF(AND(4*7+1-$I$2+1>=1,4*7+1-$I$2+1<=$I$3),4*7+1-$I$2+1,"") | B17: =IF(AND(4*7+2-$I$2+1>=1,4*7+2-$I$2+1<=$I$3),4*7+2-$I$2+1,"") | C17: =IF(AND(4*7+3-$I$2+1>=1,4*7+3-$I$2+1<=$I$3),4*7+3-$I$2+1,"") | D17: =IF(AND(4*7+4-$I$2+1>=1,4*7+4-$I$2+1<=$I$3),4*7+4-$I$2+1,"") | E17: =IF(AND(4*7+5-$I$2+1>=1,4*7+5-$I$2+1<=$I$3),4*7+5-$I$2+1,"") | F17: =IF(AND(4*7+6-$I$2+1>=1,4*7+6-$I$2+1<=$I$3),4*7+6-$I$2+1,"") | G17: =IF(AND(4*7+7-$I$2+1>=1,4*7+7-$I$2+1<=$I$3),4*7+7-$I$2+1,"")
A18: =IF(A17="","",IFERROR(INDEX('Seguimiento Diario'!$E$6:$E$36,A17)&"%","-")) | B18: =IF(B17="","",IFERROR(INDEX('Seguimiento Diario'!$E$6:$E$36,B17)&"%","-")) | C18: =IF(C17="","",IFERROR(INDEX('Seguimiento Diario'!$E$6:$E$36,C17)&"%","-")) | D18: =IF(D17="","",IFERROR(INDEX('Seguimiento Diario'!$E$6:$E$36,D17)&"%","-")) | E18: =IF(E17="","",IFERROR(INDEX('Seguimiento Diario'!$E$6:$E$36,E17)&"%","-")) | F18: =IF(F17="","",IFERROR(INDEX('Seguimiento Diario'!$E$6:$E$36,F17)&"%","-")) | G18: =IF(G17="","",IFERROR(INDEX('Seguimiento Diario'!$E$6:$E$36,G17)&"%","-"))
A19: =IF(A17="","",IFERROR("$"&TEXT(INDEX('Seguimiento Diario'!$H$6:$H$36,A17),"#,##0"),"-")) | B19: =IF(B17="","",IFERROR("$"&TEXT(INDEX('Seguimiento Diario'!$H$6:$H$36,B17),"#,##0"),"-")) | C19: =IF(C17="","",IFERROR("$"&TEXT(INDEX('Seguimiento Diario'!$H$6:$H$36,C17),"#,##0"),"-")) | D19: =IF(D17="","",IFERROR("$"&TEXT(INDEX('Seguimiento Diario'!$H$6:$H$36,D17),"#,##0"),"-")) | E19: =IF(E17="","",IFERROR("$"&TEXT(INDEX('Seguimiento Diario'!$H$6:$H$36,E17),"#,##0"),"-")) | F19: =IF(F17="","",IFERROR("$"&TEXT(INDEX('Seguimiento Diario'!$H$6:$H$36,F17),"#,##0"),"-")) | G19: =IF(G17="","",IFERROR("$"&TEXT(INDEX('Seguimiento Diario'!$H$6:$H$36,G17),"#,##0"),"-"))
A20: =IF(AND(5*7+1-$I$2+1>=1,5*7+1-$I$2+1<=$I$3),5*7+1-$I$2+1,"") | B20: =IF(AND(5*7+2-$I$2+1>=1,5*7+2-$I$2+1<=$I$3),5*7+2-$I$2+1,"") | C20: =IF(AND(5*7+3-$I$2+1>=1,5*7+3-$I$2+1<=$I$3),5*7+3-$I$2+1,"") | D20: =IF(AND(5*7+4-$I$2+1>=1,5*7+4-$I$2+1<=$I$3),5*7+4-$I$2+1,"") | E20: =IF(AND(5*7+5-$I$2+1>=1,5*7+5-$I$2+1<=$I$3),5*7+5-$I$2+1,"") | F20: =IF(AND(5*7+6-$I$2+1>=1,5*7+6-$I$2+1<=$I$3),5*7+6-$I$2+1,"") | G20: =IF(AND(5*7+7-$I$2+1>=1,5*7+7-$I$2+1<=$I$3),5*7+7-$I$2+1,"")
A21: =IF(A20="","",IFERROR(INDEX('Seguimiento Diario'!$E$6:$E$36,A20)&"%","-")) | B21: =IF(B20="","",IFERROR(INDEX('Seguimiento Diario'!$E$6:$E$36,B20)&"%","-")) | C21: =IF(C20="","",IFERROR(INDEX('Seguimiento Diario'!$E$6:$E$36,C20)&"%","-")) | D21: =IF(D20="","",IFERROR(INDEX('Seguimiento Diario'!$E$6:$E$36,D20)&"%","-")) | E21: =IF(E20="","",IFERROR(INDEX('Seguimiento Diario'!$E$6:$E$36,E20)&"%","-")) | F21: =IF(F20="","",IFERROR(INDEX('Seguimiento Diario'!$E$6:$E$36,F20)&"%","-")) | G21: =IF(G20="","",IFERROR(INDEX('Seguimiento Diario'!$E$6:$E$36,G20)&"%","-"))
A22: =IF(A20="","",IFERROR("$"&TEXT(INDEX('Seguimiento Diario'!$H$6:$H$36,A20),"#,##0"),"-")) | B22: =IF(B20="","",IFERROR("$"&TEXT(INDEX('Seguimiento Diario'!$H$6:$H$36,B20),"#,##0"),"-")) | C22: =IF(C20="","",IFERROR("$"&TEXT(INDEX('Seguimiento Diario'!$H$6:$H$36,C20),"#,##0"),"-")) | D22: =IF(D20="","",IFERROR("$"&TEXT(INDEX('Seguimiento Diario'!$H$6:$H$36,D20),"#,##0"),"-")) | E22: =IF(E20="","",IFERROR("$"&TEXT(INDEX('Seguimiento Diario'!$H$6:$H$36,E20),"#,##0"),"-")) | F22: =IF(F20="","",IFERROR("$"&TEXT(INDEX('Seguimiento Diario'!$H$6:$H$36,F20),"#,##0"),"-")) | G22: =IF(G20="","",IFERROR("$"&TEXT(INDEX('Seguimiento Diario'!$H$6:$H$36,G20),"#,##0"),"-"))
A24: LEYENDA: | B24: 🟢 80%+ | C24: 🟡 60-79% | D24: 🔴 <60% | F24: Sáb-Dom
A26: RESUMEN DEL MES
A27: Días capturados: | B27: =COUNTA('Seguimiento Diario'!E6:E36)&" de "&'Seguimiento Diario'!S6
A28: Ocupación promedio: | B28: =IFERROR(ROUND(AVERAGE('Seguimiento Diario'!E6:E36),1)&"%","-")
A29: Ingresos totales: | B29: ="$"&TEXT(SUM('Seguimiento Diario'!H6:H36),"#,##0")
A30: Días con ocupación <60%: | B30: =COUNTIF('Seguimiento Diario'!E6:E36,"<60")

Sheet Hoja1
A1: REPORTE HISTÓRICO Y PRONÓSTICO DE HABITACIONES
A2: Propiedad: INH3RI | Período: 01-Feb-2026 al 28-Feb-2026 | Habitaciones: 85
A4: FECHA | B4: OCC REAL | C4: PRONÓSTICO | D4: LLEGADAS | E4: SALIDAS | F4: VACANTES | G4: DISPONIBLES | H4: % OCC | I4: INGRESOS ($) | J4: TARIFA MEDIA | K4: REVPAR | L4: COMPS | M4: USO CASA | N4: USO DÍA | O4: NO SHOW | P4: ADULTOS | Q4: JUVENILES | R4: NIÑOS | S4: INFANTES | T4: VAR vs PRON | U4: INGRESO/HUÉSPED | V4: TASA ROTACIÓN | W4: VACANTES ACUM
A5: =DATE('Seguimiento Diario'!$S$4,VALUE(LEFT('Seguimiento Diario'!$S$3,FIND("-",'Seguimiento Diario'!$S$3)-1)),1) | B5: ='Seguimiento Diario'!E6 | C5: ='Seguimiento Diario'!D6 | D5: 69 | E5: 91 | F5: ='Seguimiento Diario'!L6 | G5: 85 | H5: =B5/G5 | I5: ='Seguimiento Diario'!H6 | J5: ='Seguimiento Diario'!G6 | K5: =I5/G5 | L5: 0 | M5: 0 | N5: 0 | O5: 0 | P5: 26 | Q5: 0 | R5: 0 | S5: 0 | T5: =B5-C5 | U5: =IF(P5>0,I5/P5,0) | V5: =IF(B5>0,(D5+E5)/2/B5,0) | W5: =SUM($F$5:F5)
A6: =DATE('Seguimiento Diario'!$S$4,VALUE(LEFT('Seguimiento Diario'!$S$3,FIND("-",'Seguimiento Diario'!$S$3)-1)),2) | B6: ='Seguimiento Diario'!E7 | C6: ='Seguimiento Diario'!D7 | D6: 0 | E6: 7 | F6: ='Seguimiento Diario'!L7 | G6: 85 | H6: =B6/G6 | I6: ='Seguimiento Diario'!H7 | J6: ='Seguimiento Diario'!G7 | K6: =I6/G6 | L6: 0 | M6: 0 | N6: 0 | O6: 0 | P6: 14 | Q6: 0 | R6: 0 | S6: 0 | T6: =B6-C6 | U6: =IF(P6>0,I6/P6,0) | V6: =IF(B6>0,(D6+E6)/2/B6,0) | W6: =SUM($F$5:F6)
A7: =DATE('Seguimiento Diario'!$S$4,VALUE(LEFT('Seguimiento Diario'!$S$3,FIND("-",'Seguimiento Diario'!$S$3)-1)),3) | B7: ='Seguimiento Diario'!E8 | C7: ='Seguimiento Diario'!D8 | D7: 1 | E7: 0 | F7: ='Seguimiento Diario'!L8 | G7: 85 | H7: =B7/G7 | I7: ='Seguimiento Diario'!H8 | J7: ='Seguimiento Diario'!G8 | K7: =I7/G7 | L7: 0 | M7: 0 | N7: 0 | O7: 0 | P7: 15 | Q7: 0 | R7: 0 | S7: 0 | T7: =B7-C7 | U7: =IF(P7>0,I7/P7,0) | V7: =IF(B7>0,(D7+E7)/2/B7,0) | W7: =SUM($F$5:F7)
A8: =DATE('Seguimiento Diario'!$S$4,VALUE(LEFT('Seguimiento Diario'!$S$3,FIND("-",'Seguimiento Diario'!$S$3)-1)),4) | B8: ='Seguimiento Diario'!E9 | C8: ='Seguimiento Diario'!D9 | D8: 1 | E8: 1 | F8: ='Seguimiento Diario'!L9 | G8: 85 | H8: =B8/G8 | I8: ='Seguimiento Diario'!H9 | J8: ='Seguimiento Diario'!G9 | K8: =I8/G8 | L8: 0 | M8: 0 | N8: 0 | O8: 0 | P8: 15 | Q8: 0 | R8: 0 | S8: 0 | T8: =B8-C8 | U8: =IF(P8>0,I8/P8,0) | V8: =IF(B8>0,(D8+E8)/2/B8,0) | W8: =SUM($F$5:F8)
A9: =DATE('Seguimiento Diario'!$S$4,VALUE(LEFT('Seguimiento Diario'!$S$3,FIND("-",'Seguimiento Diario'!$S$3)-1)),5) | B9: ='Seguimiento Diario'!E10 | C9: ='Seguimiento Diario'!D10 | D9: 14 | E9: 1 | F9: ='Seguimiento Diario'!L10 | G9: 85 | H9: =B9/G9 | I9: ='Seguimiento Diario'!H10 | J9: ='Seguimiento Diario'!G10 | K9: =I9/G9 | L9: 0 | M9: 0 | N9: 0 | O9: 0 | P9: 28 | Q9: 0 | R9: 0 | S9: 0 | T9: =B9-C9 | U9: =IF(P9>0,I9/P9,0) | V9: =IF(B9>0,(D9+E9)/2/B9,0) | W9: =SUM($F$5:F9)
A10: =DATE('Seguimiento Diario'!$S$4,VALUE(LEFT('Seguimiento Diario'!$S$3,FIND("-",'Seguimiento Diario'!$S$3)-1)),6) | B10: ='Seguimiento Diario'!E11 | C10: ='Seguimiento Diario'!D11 | D10: 2 | E10: 13 | F10: ='Seguimiento Diario'!L11 | G10: 85 | H10: =B10/G10 | I10: ='Seguimiento Diario'!H11 | J10: ='Seguimiento Diario'!G11 | K10: =I10/G10 | L10: 0 | M10: 0 | N10: 0 | O10: 0 | P10: 20 | Q10: 0 | R10: 0 | S10: 0 | T10: =B10-C10 | U10: =IF(P10>0,I10/P10,0) | V10: =IF(B10>0,(D10+E10)/2/B10,0) | W10: =SUM($F$5:F10)
A11: =DATE('Seguimiento Diario'!$S$4,VALUE(LEFT('Seguimiento Diario'!$S$3,FIND("-",'Seguimiento Diario'!$S$3)-1)),7) | B11: ='Seguimiento Diario'!E12 | C11: ='Seguimiento Diario'!D12 | D11: 0 | E11: 0 | F11: ='Seguimiento Diario'!L12 | G11: 85 | H11: =B11/G11 | I11: ='Seguimiento Diario'!H12 | J11: ='Seguimiento Diario'!G12 | K11: =I11/G11 | L11: 0 | M11: 0 | N11: 0 | O11: 0 | P11: 20 | Q11: 0 | R11: 0 | S11: 0 | T11: =B11-C11 | U11: =IF(P11>0,I11/P11,0) | V11: =IF(B11>0,(D11+E11)/2/B11,0) | W11: =SUM($F$5:F11)
A12: =DATE('Seguimiento Diario'!$S$4,VALUE(LEFT('Seguimiento Diario'!$S$3,FIND("-",'Seguimiento Diario'!$S$3)-1)),8) | B12: ='Seguimiento Diario'!E13 | C12: ='Seguimiento Diario'!D13 | D12: 0 | E12: 2 | F12: ='Seguimiento Diario'!L13 | G12: 85 | H12: =B12/G12 | I12: ='Seguimiento Diario'!H13 | J12: ='Seguimiento Diario'!G13 | K12: =I12/G12 | L12: 0 | M12: 0 | N12: 0 | O12: 0 | P12: 16 | Q12: 0 | R12: 0 | S12: 0 | T12: =B12-C12 | U12: =IF(P12>0,I12/P12,0) | V12: =IF(B12>0,(D12+E12)/2/B12,0) | W12: =SUM($F$5:F12)
A13: =DATE('Seguimiento Diario'!$S$4,VALUE(LEFT('Seguimiento Diario'!$S$3,FIND("-",'Seguimiento Diario'!$S$3)-1)),9) | B13: ='Seguimiento Diario'!E14 | C13: ='Seguimiento Diario'!D14 | D13: 13 | E13: 1 | F13: ='Seguimiento Diario'!L14 | G13: 85 | H13: =B13/G13 | I13: ='Seguimiento Diario'!H14 | J13: ='Seguimiento Diario'!G14 | K13: =I13/G13 | L13: 0 | M13: 0 | N13: 0 | O13: 0 | P13: 23 | Q13: 0 | R13: 0 | S13: 0 | T13: =B13-C13 | U13: =IF(P13>0,I13/P13,0) | V13: =IF(B13>0,(D13+E13)/2/B13,0) | W13: =SUM($F$5:F13)
A14: =DATE('Seguimiento Diario'!$S$4,VALUE(LEFT('Seguimiento Diario'!$S$3,FIND("-",'Seguimiento Diario'!$S$3)-1)),10) | B14: ='Seguimiento Diario'!E15 | C14: ='Seguimiento Diario'!D15 | D14: 0 | E14: 0 | F14: ='Seguimiento Diario'!L15 | G14: 85 | H14: =B14/G14 | I14: ='Seguimiento Diario'!H15 | J14: ='Seguimiento Diario'!G15 | K14: =I14/G14 | L14: 0 | M14: 0 | N14: 0 | O14: 0 | P14: 23 | Q14: 0 | R14: 0 | S14: 0 | T14: =B14-C14 | U14: =IF(P14>0,I14/P14,0) | V14: =IF(B14>0,(D14+E14)/2/B14,0) | W14: =SUM($F$5:F14)
A15: =DATE('Seguimiento Diario'!$S$4,VALUE(LEFT('Seguimiento Diario'!$S$3,FIND("-",'Seguimiento Diario'!$S$3)-1)),11) | B15: ='Seguimiento Diario'!E16 | C15: ='Seguimiento Diario'!D16 | D15: 0 | E15: 0 | F15: ='Seguimiento Diario'!L16 | G15: 85 | H15: =B15/G15 | I15: ='Seguimiento Diario'!H16 | J15: ='Seguimiento Diario'!G16 | K15: =I15/G15 | L15: 0 | M15: 0 | N15: 0 | O15: 0 | P15: 23 | Q15: 0 | R15: 0 | S15: 0 | T15: =B15-C15 | U15: =IF(P15>0,I15/P15,0) | V15: =IF(B15>0,(D15+E15)/2/B15,0) | W15: =SUM($F$5:F15)
A16: =DATE('Seguimiento Diario'!$S$4,VALUE(LEFT('Seguimiento Diario'!$S$3,FIND("-",'Seguimiento Diario'!$S$3)-1)),12) | B16: ='Seguimiento Diario'!E17 | C16: ='Seguimiento Diario'!D17 | D16: 2 | E16: 0 | F16: ='Seguimiento Diario'!L17 | G16: 85 | H16: =B16/G16 | I16: ='Seguimiento Diario'!H17 | J16: ='Seguimiento Diario'!G17 | K16: =I16/G16 | L16: 0 | M16: 0 | N16: 0 | O16: 0 | P16: 27 | Q16: 0 | R16: 0 | S16: 0 | T16: =B16-C16 | U16: =IF(P16>0,I16/P16,0) | V16: =IF(B16>0,(D16+E16)/2/B16,0) | W16: =SUM($F$5:F16)
A17: =DATE('Seguimiento Diario'!$S$4,VALUE(LEFT('Seguimiento Diario'!$S$3,FIND("-",'Seguimiento Diario'!$S$3)-1)),13) | B17: ='Seguimiento Diario'!E18 | C17: ='Seguimiento Diario'!D18 | D17: 1 | E17: 13 | F17: ='Seguimiento Diario'!L18 | G17: 85 | H17: =B17/G17 | I17: ='Seguimiento Diario'!H18 | J17: ='Seguimiento Diario'!G18 | K17: =I17/G17 | L17: 0 | M17: 0 | N17: 0 | O17: 0 | P17: 20 | Q17: 0 | R17: 0 | S17: 0 | T17: =B17-C17 | U17: =IF(P17>0,I17/P17,0) | V17: =IF(B17>0,(D17+E17)/2/B17,0) | W17: =SUM($F$5:F17)
A18: =DATE('Seguimiento Diario'!$S$4,VALUE(LEFT('Seguimiento Diario'!$S$3,FIND("-",'Seguimiento Diario'!$S$3)-1)),14) | B18: ='Seguimiento Diario'!E19 | C18: ='Seguimiento Diario'!D19 | D18: 6 | E18: 1 | F18: ='Seguimiento Diario'!L19 | G18: 85 | H18: =B18/G18 | I18: ='Seguimiento Diario'!H19 | J18: ='Seguimiento Diario'!G19 | K18: =I18/G18 | L18: 0 | M18: 0 | N18: 0 | O18: 0 | P18: 29 | Q18: 0 | R18: 1 | S18: 0 | T18: =B18-C18 | U18: =IF(P18>0,I18/P18,0) | V18: =IF(B18>0,(D18+E18)/2/B18,0) | W18: =SUM($F$5:F18)
A19: =DATE('Seguimiento Diario'!$S$4,VALUE(LEFT('Seguimiento Diario'!$S$3,FIND("-",'Seguimiento Diario'!$S$3)-1)),15) | B19: ='Seguimiento Diario'!E20 | C19: ='Seguimiento Diario'!D20 | D19: 0 | E19: 6 | F19: ='Seguimiento Diario'!L20 | G19: 85 | H19: =B19/G19 | I19: ='Seguimiento Diario'!H20 | J19: ='Seguimiento Diario'!G20 | K19: =I19/G19 | L19: 0 | M19: 0 | N19: 0 | O19: 0 | P19: 18 | Q19: 0 | R19: 0 | S19: 0 | T19: =B19-C19 | U19: =IF(P19>0,I19/P19,0) | V19: =IF(B19>0,(D19+E19)/2/B19,0) | W19: =SUM($F$5:F19)
A20: =DATE('Seguimiento Diario'!$S$4,VALUE(LEFT('Seguimiento Diario'!$S$3,FIND("-",'Seguimiento Diario'!$S$3)-1)),16) | B20: ='Seguimiento Diario'!E21 | C20: ='Seguimiento Diario'!D21 | D20: 69 | E20: 68 | F20: ='Seguimiento Diario'!L21 | G20: 85 | H20: =B20/G20 | I20: ='Seguimiento Diario'!H21 | J20: ='Seguimiento Diario'!G21 | K20: =I20/G20 | L20: 0 | M20: 0 | N20: 0 | O20: 0 | P20: 82 | Q20: 0 | R20: 0 | S20: 0 | T20: =B20-C20 | U20: =IF(P20>0,I20/P20,0) | V20: =IF(B20>0,(D20+E20)/2/B20,0) | W20: =SUM($F$5:F20)
A21: =DATE('Seguimiento Diario'!$S$4,VALUE(LEFT('Seguimiento Diario'!$S$3,FIND("-",'Seguimiento Diario'!$S$3)-1)),17) | B21: ='Seguimiento Diario'!E22 | C21: ='Seguimiento Diario'!D22 | D21: 2 | E21: 0 | F21: ='Seguimiento Diario'!L22 | G21: 85 | H21: =B21/G21 | I21: ='Seguimiento Diario'!H22 | J21: ='Seguimiento Diario'!G22 | K21: =I21/G21 | L21: 0 | M21: 0 | N21: 0 | O21: 0 | P21: 85 | Q21: 0 | R21: 0 | S21: 0 | T21: =B21-C21 | U21: =IF(P21>0,I21/P21,0) | V21: =IF(B21>0,(D21+E21)/2/B21,0) | W21: =SUM($F$5:F21)
A22: =DATE('Seguimiento Diario'!$S$4,VALUE(LEFT('Seguimiento Diario'!$S$3,FIND("-",'Seguimiento Diario'!$S$3)-1)),18) | B22: ='Seguimiento Diario'!E23 | C22: ='Seguimiento Diario'!D23 | D22: 0 | E22: 1 | F22: ='Seguimiento Diario'!L23 | G22: 85 | H22: =B22/G22 | I22: ='Seguimiento Diario'!H23 | J22: ='Seguimiento Diario'!G23 | K22: =I22/G22 | L22: 0 | M22: 0 | N22: 0 | O22: 0 | P22: 83 | Q22: 0 | R22: 0 | S22: 0 | T22: =B22-C22 | U22: =IF(P22>0,I22/P22,0) | V22: =IF(B22>0,(D22+E22)/2/B22,0) | W22: =SUM($F$5:F22)
A23: =DATE('Seguimiento Diario'!$S$4,VALUE(LEFT('Seguimiento Diario'!$S$3,FIND("-",'Seguimiento Diario'!$S$3)-1)),19) | B23: ='Seguimiento Diario'!E24 | C23: ='Seguimiento Diario'!D24 | D23: 0 | E23: 0 | F23: ='Seguimiento Diario'!L24 | G23: 85 | H23: =B23/G23 | I23: ='Seguimiento Diario'!H24 | J23: ='Seguimiento Diario'!G24 | K23: =I23/G23 | L23: 0 | M23: 0 | N23: 0 | O23: 0 | P23: 83 | Q23: 0 | R23: 0 | S23: 0 | T23: =B23-C23 | U23: =IF(P23>0,I23/P23,0) | V23: =IF(B23>0,(D23+E23)/2/B23,0) | W23: =SUM($F$5:F23)
A24: =DATE('Seguimiento Diario'!$S$4,VALUE(LEFT('Seguimiento Diario'!$S$3,FIND("-",'Seguimiento Diario'!$S$3)-1)),20) | B24: ='Seguimiento Diario'!E25 | C24: ='Seguimiento Diario'!D25 | D24: 15 | E24: 1 | F24: ='Seguimiento Diario'!L25 | G24: 85 | H24: =B24/G24 | I24: ='Seguimiento Diario'!H25 | J24: ='Seguimiento Diario'!G25 | K24: =I24/G24 | L24: 1 | M24: 0 | N24: 0 | O24: 0 | P24: 119 | Q24: 0 | R24: 1 | S24: 0 | T24: =B24-C24 | U24: =IF(P24>0,I24/P24,0) | V24: =IF(B24>0,(D24+E24)/2/B24,0) | W24: =SUM($F$5:F24)
A25: =DATE('Seguimiento Diario'!$S$4,VALUE(LEFT('Seguimiento Diario'!$S$3,FIND("-",'Seguimiento Diario'!$S$3)-1)),21) | B25: ='Seguimiento Diario'!E26 | C25: ='Seguimiento Diario'!D26 | D25: 0 | E25: 14 | F25: ='Seguimiento Diario'!L26 | G25: 85 | H25: =B25/G25 | I25: ='Seguimiento Diario'!H26 | J25: ='Seguimiento Diario'!G26 | K25: =I25/G25 | L25: 0 | M25: 0 | N25: 0 | O25: 0 | P25: 84 | Q25: 0 | R25: 0 | S25: 0 | T25: =B25-C25 | U25: =IF(P25>0,I25/P25,0) | V25: =IF(B25>0,(D25+E25)/2/B25,0) | W25: =SUM($F$5:F25)
A26: =DATE('Seguimiento Diario'!$S$4,VALUE(LEFT('Seguimiento Diario'!$S$3,FIND("-",'Seguimiento Diario'!$S$3)-1)),22) | B26: ='Seguimiento Diario'!E27 | C26: ='Seguimiento Diario'!D27 | D26: 0 | E26: 1 | F26: ='Seguimiento Diario'!L27 | G26: 85 | H26: =B26/G26 | I26: ='Seguimiento Diario'!H27 | J26: ='Seguimiento Diario'!G27 | K26: =I26/G26 | L26: 0 | M26: 0 | N26: 0 | O26: 0 | P26: 82 | Q26: 0 | R26: 0 | S26: 0 | T26: =B26-C26 | U26: =IF(P26>0,I26/P26,0) | V26: =IF(B26>0,(D26+E26)/2/B26,0) | W26: =SUM($F$5:F26)
A27: =DATE('Seguimiento Diario'!$S$4,VALUE(LEFT('Seguimiento Diario'!$S$3,FIND("-",'Seguimiento Diario'!$S$3)-1)),23) | B27: ='Seguimiento Diario'!E28 | C27: ='Seguimiento Diario'!D28 | D27: 0 | E27: 0 | F27: ='Seguimiento Diario'!L28 | G27: 85 | H27: =B27/G27 | I27: ='Seguimiento Diario'!H28 | J27: ='Seguimiento Diario'!G28 | K27: =I27/G27 | L27: 0 | M27: 0 | N27: 0 | O27: 0 | P27: 82 | Q27: 0 | R27: 0 | S27: 0 | T27: =B27-C27 | U27: =IF(P27>0,I27/P27,0) | V27: =IF(B27>0,(D27+E27)/2/B27,0) | W27: =SUM($F$5:F27)
A28: =DATE('Seguimiento Diario'!$S$4,VALUE(LEFT('Seguimiento Diario'!$S$3,FIND("-",'Seguimiento Diario'!$S$3)-1)),24) | B28: ='Seguimiento Diario'!E29 | C28: ='Seguimiento Diario'!D29 | D28: 0 | E28: 0 | F28: ='Seguimiento Diario'!L29 | G28: 85 | H28: =B28/G28 | I28: ='Seguimiento Diario'!H29 | J28: ='Seguimiento Diario'!G29 | K28: =I28/G28 | L28: 0 | M28: 0 | N28: 0 | O28: 0 | P28: 82 | Q28: 0 | R28: 0 | S28: 0 | T28: =B28-C28 | U28: =IF(P28>0,I28/P28,0) | V28: =IF(B28>0,(D28+E28)/2/B28,0) | W28: =SUM($F$5:F28)
A29: =DATE('Seguimiento Diario'!$S$4,VALUE(LEFT('Seguimiento Diario'!$S$3,FIND("-",'Seguimiento Diario'!$S$3)-1)),25) | B29: ='Seguimiento Diario'!E30 | C29: ='Seguimiento Diario'!D30 | D29: 0 | E29: 0 | F29: ='Seguimiento Diario'!L30 | G29: 85 | H29: =B29/G29 | I29: ='Seguimiento Diario'!H30 | J29: ='Seguimiento Diario'!G30 | K29: =I29/G29 | L29: 0 | M29: 0 | N29: 0 | O29: 0 | P29: 82 | Q29: 0 | R29: 0 | S29: 0 | T29: =B29-C29 | U29: =IF(P29>0,I29/P29,0) | V29: =IF(B29>0,(D29+E29)/2/B29,0) | W29: =SUM($F$5:F29)
A30: =DATE('Seguimiento Diario'!$S$4,VALUE(LEFT('Seguimiento Diario'!$S$3,FIND("-",'Seguimiento Diario'!$S$3)-1)),26) | B30: ='Seguimiento Diario'!E31 | C30: ='Seguimiento Diario'!D31 | D30: 0 | E30: 0 | F30: ='Seguimiento Diario'!L31 | G30: 85 | H30: =B30/G30 | I30: ='Seguimiento Diario'!H31 | J30: ='Seguimiento Diario'!G31 | K30: =I30/G30 | L30: 0 | M30: 0 | N30: 0 | O30: 0 | P30: 82 | Q30: 0 | R30: 0 | S30: 0 | T30: =B30-C30 | U30: =IF(P30>0,I30/P30,0) | V30: =IF(B30>0,(D30+E30)/2/B30,0) | W30: =SUM($F$5:F30)
A31: =DATE('Seguimiento Diario'!$S$4,VALUE(LEFT('Seguimiento Diario'!$S$3,FIND("-",'Seguimiento Diario'!$S$3)-1)),27) | B31: ='Seguimiento Diario'!E32 | C31: ='Seguimiento Diario'!D32 | D31: 15 | E31: 0 | F31: ='Seguimiento Diario'!L32 | G31: 85 | H31: =B31/G31 | I31: ='Seguimiento Diario'!H32 | J31: ='Seguimiento Diario'!G32 | K31: =I31/G31 | L31: 0 | M31: 0 | N31: 0 | O31: 0 | P31: 84 | Q31: 0 | R31: 0 | S31: 0 | T31: =B31-C31 | U31: =IF(P31>0,I31/P31,0) | V31: =IF(B31>0,(D31+E31)/2/B31,0) | W31: =SUM($F$5:F31)
A32: =DATE('Seguimiento Diario'!$S$4,VALUE(LEFT('Seguimiento Diario'!$S$3,FIND("-",'Seguimiento Diario'!$S$3)-1)),28) | B32: ='Seguimiento Diario'!E33 | C32: ='Seguimiento Diario'!D33 | D32: 1 | E32: 15 | F32: ='Seguimiento Diario'!L33 | G32: 85 | H32: =B32/G32 | I32: ='Seguimiento Diario'!H33 | J32: ='Seguimiento Diario'!G33 | K32: =I32/G32 | L32: 0 | M32: 0 | N32: 0 | O32: 0 | P32: 84 | Q32: 0 | R32: 0 | S32: 0 | T32: =B32-C32 | U32: =IF(P32>0,I32/P32,0) | V32: =IF(B32>0,(D32+E32)/2/B32,0) | W32: =SUM($F$5:F32)
A33: =IFERROR(IF('Seguimiento Diario'!$S$6>=29,DATE('Seguimiento Diario'!$S$4,VALUE(LEFT('Seguimiento Diario'!$S$3,FIND("-",'Seguimiento Diario'!$S$3)-1)),29),""),"") | B33: ='Seguimiento Diario'!E34 | C33: ='Seguimiento Diario'!D34 | F33: ='Seguimiento Diario'!L34 | G33: =IF('Seguimiento Diario'!E34<>"",85,0) | H33: =IFERROR(IF(G33>0,B33/G33,""),"") | I33: ='Seguimiento Diario'!H34 | J33: ='Seguimiento Diario'!G34 | K33: =IFERROR(IF(G33>0,I33/G33,""),"") | T33: =IF(B33<>"",B33-C33,"") | U33: =IFERROR(IF(B33>0,I33/B33,0),0) | V33: =IFERROR(IF(B33>0,(D33+E33)/2/B33,0),0) | W33: =SUM($F$5:F33)
A34: =IFERROR(IF('Seguimiento Diario'!$S$6>=30,DATE('Seguimiento Diario'!$S$4,VALUE(LEFT('Seguimiento Diario'!$S$3,FIND("-",'Seguimiento Diario'!$S$3)-1)),30),""),"") | B34: ='Seguimiento Diario'!E35 | C34: ='Seguimiento Diario'!D35 | F34: ='Seguimiento Diario'!L35 | G34: =IF('Seguimiento Diario'!E35<>"",85,0) | H34: =IFERROR(IF(G34>0,B34/G34,""),"") | I34: ='Seguimiento Diario'!H35 | J34: ='Seguimiento Diario'!G35 | K34: =IFERROR(IF(G34>0,I34/G34,""),"") | T34: =IF(B34<>"",B34-C34,"") | U34: =IFERROR(IF(B34>0,I34/B34,0),0) | V34: =IFERROR(IF(B34>0,(D34+E34)/2/B34,0),0) | W34: =SUM($F$5:F34)
A35: =IFERROR(IF('Seguimiento Diario'!$S$6>=31,DATE('Seguimiento Diario'!$S$4,VALUE(LEFT('Seguimiento Diario'!$S$3,FIND("-",'Seguimiento Diario'!$S$3)-1)),31),""),"") | B35: ='Seguimiento Diario'!E36 | C35: ='Seguimiento Diario'!D36 | F35: ='Seguimiento Diario'!L36 | G35: =IF('Seguimiento Diario'!E36<>"",85,0) | H35: =IFERROR(IF(G35>0,B35/G35,""),"") | I35: ='Seguimiento Diario'!H36 | J35: ='Seguimiento Diario'!G36 | K35: =IFERROR(IF(G35>0,I35/G35,""),"") | T35: =IF(B35<>"",B35-C35,"") | U35: =IFERROR(IF(B35>0,I35/B35,0),0) | V35: =IFERROR(IF(B35>0,(D35+E35)/2/B35,0),0) | W35: =SUM($F$5:F35)
Y36: FECHA | Z36: INGRESOS
A37: =IF('Seguimiento Diario'!S3<>"", "TOTALES "&'Seguimiento Diario'!S3, "TOTALES") | B37: =SUM(B5:B35) | C37: =SUM(C5:C35) | D37: =SUM(D5:D35) | E37: =SUM(E5:E35) | F37: =SUM(F5:F35) | G37: =SUMIF(G5:G35,">0") | H37: =IFERROR(IF(G37>0,B37/G37,""),"") | I37: =SUM(I5:I35) | J37: =IFERROR(AVERAGEIF(J5:J35,">0"),"") | K37: =IFERROR(IF(G37>0,I37/G37,""),"") | L37: =SUMIF(L5:L35,"<>") | M37: =SUMIF(M5:M35,"<>") | N37: =SUMIF(N5:N35,"<>") | O37: =SUMIF(O5:O35,"<>") | P37: =SUMIF(P5:P35,"<>") | Q37: =SUMIF(Q5:Q35,"<>") | R37: =SUMIF(R5:R35,"<>") | S37: 0 | T37: =SUM(T5:T35) | U37: =IFERROR(AVERAGEIF(U5:U35,">0"),"") | V37: =IFERROR(AVERAGEIF(V5:V35,">0"),"") | W37: =MAX(W5:W35) | Y37: =A5 | Z37: =I5
Y38: =A6 | Z38: =I6
Y39: =A7 | Z39: =I7
Y40: =A8 | Z40: =I8
Y41: =A9 | Z41: =I9
...

Sheet Análisis y Recomendaciones
A1: =IF(COUNTA('Seguimiento Diario'!E6:E36)<28, "⚠️ ANÁLISIS PARCIAL: Basado en "&COUNTA('Seguimiento Diario'!E6:E36)&" de 28 días. Los datos pueden cambiar.", "✅ ANÁLISIS COMPLETO: Mes cerrado con 28 días.")
A2: 20 PUNTOS DE MEJORA - ANÁLISIS FEBRERO 2026
A3: ="Propiedad INH3RI | 85 Habitaciones | Ocupación: "&TEXT(Hoja1!H37,"0.00%")&" ("&COUNTA('Seguimiento Diario'!E6:E36)&" días)"
A5: # | B5: ÁREA | C5: HALLAZGO / PROBLEMA | D5: RECOMENDACIÓN DE MEJORA | E5: VALIDEZ
A6: 1 | B6: PRONÓSTICO | C6: ="Error promedio del "&TEXT(1-'Dashboard KPIs'!C8,"0%")&" en pronósticos. "&IF(Hoja1!T37<0,"Variación de "&ABS(Hoja1!T37)&" habs vs pronóstico.","Meta superada.") | D6: Revisar metodología de pronóstico. Ajustar modelo usando datos históricos reales y estacionalidad. | E6: ✓
A7: 2 | B7: OCUPACIÓN DOMINGOS | C7: Domingos con solo 81.5% de ocupación promedio (el más bajo de la semana). | D7: Crear paquetes especiales "Domingo Relax" o tarifas promocionales para extender estancias. | E7: =IF(COUNTA('Seguimiento Diario'!E6:E36)>=7,"✓","⚠")
A8: 3 | B8: INGRESOS PERDIDOS | C8: =Hoja1!F37&" noches-habitación vacantes = $"&TEXT(Hoja1!F37*Hoja1!J37,"#,##0")&" en ingresos potenciales perdidos." | D8: Implementar revenue management dinámico. Bajar tarifas en días de baja demanda anticipada. | E8: ✓
A9: 4 | B9: DÍAS CRÍTICOS | C9: 2-4 Feb y 8 Feb con ocupación <80% (hasta 19 habitaciones vacías). | D9: Analizar causas de baja demanda. Coordinar con eventos locales o crear promociones específicas. | E9: =IF(COUNTA('Seguimiento Diario'!E6:E36)>=7,"✓","⚠")
A10: 5 | B10: TARIFA MÍNIMA | C10: Tarifa mínima de $750 se repite en 12 días (43% del mes). Posible piso muy bajo. | D10: Evaluar si $750 es rentable. Considerar elevar piso tarifario a $770-780 o agregar valor. | E10: =IF(COUNTA('Seguimiento Diario'!E6:E36)>=14,"✓","⚠")
A11: 6 | B11: GRUPOS | C11: OCC GRUPO = 0 todo el mes. No hay segmento grupal. | D11: Desarrollar estrategia para captar grupos corporativos, bodas, convenciones. | E11: ✓
A12: 7 | B12: RATIO HUÉSPEDES | C12: =IFERROR(TEXT(Hoja1!P37/Hoja1!B37,"0.00")&" adultos por habitación. "&IF(Hoja1!P37/Hoja1!B37<1,"Bajo aprovechamiento de capacidad.","Buen ratio de ocupación."), "-") | D12: Promocionar tarifas para 2 personas, paquetes románticos, ofertas "trae acompañante". | E12: =IF(COUNTA('Seguimiento Diario'!E6:E36)>=7,"✓","⚠")
A13: 8 | B13: SEGMENTO FAMILIAS | C13: ="Solo "&Hoja1!R37&" niños en todo el mes. "&IF(Hoja1!R37<10,"Mercado familiar prácticamente nulo.","Segmento familiar presente.") | D13: Si se desea este segmento: crear paquetes familiares, amenidades para niños. | E13: =IF(COUNTA('Seguimiento Diario'!E6:E36)>=7,"✓","⚠")
A14: 9 | B14: LLEGADAS/SALIDAS | C14: 16 Feb tuvo 69 llegadas Y 68 salidas el mismo día. Operación muy intensa. | D14: Planificar housekeeping adicional en días de alto turnover. Evitar overbooking. | E14: ✓
A15: 10 | B15: ESTANCIA PROMEDIO | C15: =IFERROR(Hoja1!D37&" llegadas para "&Hoja1!B37&" noches ocupadas = ~"&TEXT(Hoja1!B37/Hoja1!D37,"0.0")&" noches promedio de estancia.", "-") | D15: Estancia buena. Premiar estancias largas con descuentos progresivos o upgrades. | E15: =IF(COUNTA('Seguimiento Diario'!E6:E36)>=7,"✓","⚠")
A16: 11 | B16: REVPAR | C16: ="RevPAR de $"&TEXT(Hoja1!K37,"#,##0.00")&IF(Hoja1!K37>=700," supera la meta de $700."," está por debajo de la meta de $700.") | D16: Meta: llevar RevPAR a $700+ optimizando ocupación sin sacrificar tarifa. | E16: =IF(COUNTA('Seguimiento Diario'!E6:E36)>=7,"✓","⚠")
A17: 12 | B17: PICOS DE DEMANDA | C17: 20 y 27 Feb con 98.82% ocupación (84 de 85 habs). Casi lleno. | D17: En días de alta demanda: subir tarifas 10-15%. Implementar yield management. | E17: =IF(COUNTA('Seguimiento Diario'!E6:E36)>=14,"✓","⚠")
A18: 13 | B18: USO CASA | C18: ="USO CASA = "&Hoja1!M37&" todo el mes. "&IF(Hoja1!M37=0,"Bien controlado.","Revisar política.") | D18: Mantener política estricta de uso interno de habitaciones. | E18: ✓
A19: 14 | B19: INASISTENCIAS | C19: ="NO-SHOWS = "&Hoja1!O37&" todo el mes. "&IF(Hoja1!O37=0,"Excelente política de garantía.","Revisar política de cancelación.") | D19: Excelente. Política de garantía/cancelación funciona. Documentar y replicar. | E19: ✓
A20: 15 | B20: COMPS | C20: =Hoja1!L37&" COMP(s) (cortesía) en el mes. "&IF(Hoja1!L37<=2,"Bajo nivel es positivo.","Revisar política de comps.") | D20: Bajo nivel de comps es positivo. Usar comps para influencers o clientes VIP. | E20: ✓
A21: 16 | B21: VARIABILIDAD TARIFA | C21: =IFERROR("Rango tarifario: $"&MIN(Hoja1!J5:J32)&" - $"&MAX(Hoja1!J5:J32)&" ("&TEXT((MAX(Hoja1!J5:J32)-MIN(Hoja1!J5:J32))/MIN(Hoja1!J5:J32),"0%")&" de variación).", "-") | D21: Implementar tarifas más dinámicas. Alta demanda +20%, baja demanda -10%. | E21: =IF(COUNTA('Seguimiento Diario'!E6:E36)>=14,"✓","⚠")
A22: 17 | B22: CANALES | C22: No hay datos de canales de venta (OTAs, directo, corporativo). | D22: Agregar columna de canal de reserva para optimizar mix y reducir comisiones. | E22: -
A23: 18 | B23: SEGMENTACIÓN | C23: No hay segmentación de mercado visible (business, leisure, etc.). | D23: Agregar campo de segmento para análisis más profundo. | E23: -
A24: 19 | B24: TIPO HABITACIÓN | C24: No hay desglose por tipo de habitación (sencilla, doble, suite). | D24: Incluir análisis por tipo para optimizar inventario y pricing por categoría. | E24: -
A25: 20 | B25: USO DÍA | C25: ="USO DÍA = "&Hoja1!N37&" todo el mes. "&IF(Hoja1!N37=0,"No hay day-use. Oportunidad de mercado.","Day-use activo.") | D25: Explorar mercado de day-use para crews, viajeros en tránsito, parejas locales. | E25: ✓
A27: RESUMEN DE IMPACTO POTENCIAL
A28: =IF(COUNTA('Seguimiento Diario'!E6:E36)<28, "(Proyecciones basadas en "&COUNTA('Seguimiento Diario'!E6:E36)&" días - resultados pueden variar)", "")
A29: MÉTRICA | B29: ACTUAL | C29: META SUGERIDA | D29: IMPACTO ESTIMADO
A30: Ocupación | B30: =Hoja1!H37 | C30: 0.9 | D30: =IF(B29>=C29,"✅ Meta superada","+$"&TEXT((C29-B29)*85*'Seguimiento Diario'!$S$6*B30,"#,##0")&"/mes")
A31: Tarifa Promedio | B31: =Hoja1!J37 | C31: 800 | D31: =IF(B30>=C30,"✅ Meta superada","+$"&TEXT((C30-B30)*Hoja1!B37,"#,##0")&"/mes")
A32: RevPAR | B32: =Hoja1!K37 | C32: 720 | D32: =IF(B31>=C31,"✅ Meta superada","+$"&TEXT((C31-B31)*85*'Seguimiento Diario'!$S$6,"#,##0")&"/mes")
A33: Precisión Pronóstico | B33: ='Dashboard KPIs'!C8 | C33: 0.95 | D33: Mejor planificación
A35: LEYENDA DE PRIORIDAD:
A36: ● CRÍTICO | B36: Acción inmediata requerida
A37: ● IMPORTANTE | B37: Implementar en 30 días
A38: ● OPTIMIZACIÓN | B38: Mejora continua
A39: ● DATOS | B39: Mejorar recopilación de información

Sheet Dashboard KPIs
A1: DASHBOARD DE KPIs - FEBRERO 2026
A2: Propiedad: INH3RI | 85 Habitaciones | 28 días analizados
A4: KPI | B4: META | C4: ACTUAL | D4: VARIACIÓN | E4: STATUS | F4: TENDENCIA | G4: ACCIÓN SUGERIDA
A5: Ocupación (%) | B5: ≥85% | C5: =IFERROR(Hoja1!H37, "-") | D5: =IFERROR(C5-0.85, "-") | E5: =IF(C5>=0.85,"🟢",IF(C5>=0.8,"🟡","🔴")) | F5: → Estable | G5: Aumentar promociones fin de semana
A6: RevPAR ($) | B6: ≥$700 | C6: =IFERROR(Hoja1!K37, "-") | D6: =IFERROR(C6-700, "-") | E6: =IF(C6>=700,"🟢",IF(C6>=600,"🟡","🔴")) | F6: ↗ Mejorando | G6: Subir tarifas en días de alta demanda
A7: Tarifa Media ($) | B7: ≥$780 | C7: =IFERROR(Hoja1!J37, "-") | D7: =IFERROR(C7-780, "-") | E7: =IF(C7>=780,"🟢",IF(C7>=750,"🟡","🔴")) | F7: → Estable | G7: Implementar pricing dinámico
A8: Precisión Pronóstico (%) | B8: ≥90% | C8: =IFERROR(1-(ABS(Hoja1!T37)/Hoja1!C37), "-") | D8: =IFERROR(C8-0.9, "-") | E8: =IF(C8>=0.9,"🟢",IF(C8>=0.85,"🟡","🔴")) | F8: ↘ Bajando | G8: Revisar modelo de forecasting
A9: Ingresos Totales ($) | B9: ≥$1.6M | C9: =IFERROR(Hoja1!I37, "-") | D9: =IFERROR(C9-1600000, "-") | E9: =IF(C9>=1600000,"🟢",IF(C9>=1400000,"🟡","🔴")) | F9: → Estable | G9: Captar segmento grupos
A10: No-Shows | B10: 0 | C10: =IFERROR(Hoja1!O37, "-") | D10: =IFERROR(C10-0, "-") | E10: =IF(C10=0,"🟢",IF(C10<=5,"🟡","🔴")) | F10: ✓ Perfecto | G10: Mantener política actual
A11: Ocupación Grupos | B11: ≥10% | C11: =IFERROR(Hoja1!I37/Hoja1!B37, "-") | D11: =IFERROR(0-0.1, "-") | E11: =IF(0>=0.1,"🟢",IF(0>=0.05,"🟡","🔴")) | F11: ⚠ Sin datos | G11: Desarrollar estrategia de grupos
A12: Habitaciones Vacantes | B12: ≤300 | C12: =IFERROR(Hoja1!F37, "-") | D12: =IFERROR(C12-300, "-") | E12: =IF(C12<=300,"🟢",IF(C12<=400,"🟡","🔴")) | F12: ↘ Subiendo | G12: Revenue management dinámico
A14: RESUMEN EJECUTIVO
A16: KPIs en Meta (Verde): | B16: =COUNTIF(E5:E12,"🟢")&" de 8" | C16: =IFERROR(COUNTIF(E5:E12,"🟢")/8, "-") | E16: LEYENDA:
A17: KPIs Cerca (Amarillo): | B17: =COUNTIF(E5:E12,"🟡")&" de 8" | C17: =IFERROR(COUNTIF(E5:E12,"🟡")/8, "-") | E17: 🟢 Verde | F17: Meta alcanzada
A18: KPIs Críticos (Rojo): | B18: =COUNTIF(E5:E12,"🔴")&" de 8" | C18: =IFERROR(COUNTIF(E5:E12,"🔴")/8, "-") | E18: 🟡 Amarillo | F18: Cerca de meta (<5% desviación)
E19: 🔴 Rojo | F19: Requiere acción inmediata
A21: OPORTUNIDAD DE MEJORA: | B21: 274001 | C21: en ingresos perdidos por 360 habitaciones vacantes
A23: ANÁLISIS POR DÍA DE SEMANA
A25: DÍA | B25: OCC PROM | C25: TARIFA PROM | D25: INGRESOS PROM | E25: REVPAR PROM | F25: RANKING | G25: RECOMENDACIÓN
A26: Lunes | B26: 0.832 | C26: 754.72 | D26: 53435 | E26: 628.65 | F26: #5 | G26: Promociones inicio de semana
A27: Martes | B27: 0.841 | C27: 756.44 | D27: 54120.34 | E27: 636.71 | F27: #3 | G27: Mantener estrategia actual
A28: Miércoles | B28: 0.838 | C28: 757 | D28: 53965.02 | E28: 634.88 | F28: #4 | G28: Mantener estrategia actual
A29: Jueves | B29: 0.882 | C29: 761.75 | D29: 57190.08 | E29: 672.82 | F29: #2 | G29: Subir tarifa 5%
A30: Viernes | B30: 0.9 | C30: 772.32 | D30: 59161.92 | E30: 696.02 | F30: 🏆 #1 | G30: ⬆ Subir tarifa 10-15%
A31: Sábado | B31: 0.832 | C31: 764.27 | D31: 54092.25 | E31: 636.38 | F31: #6 | G31: Paquetes fin de semana
A32: Domingo | B32: 0.815 | C32: 761.31 | D32: 52749.46 | E32: 620.58 | F32: ⚠ #7 | G32: ⬇ Promo "Domingo Relax"
A34: INSIGHTS CLAVE:
A35: 🏆 Mejor día: | B35: VIERNES | C35: 90% ocupación, $696 RevPAR | E35: → Oportunidad de subir tarifas
A36: ⚠ Peor día: | B36: DOMINGO | C36: 81.5% ocupación, $621 RevPAR | E36: → Crear promociones específicas
A37: 💰 Diferencia RevPAR: | B37: 75.44 | C37: entre mejor y peor día | E37: =IFERROR( Potencial de +$6,400/mes,"")
A39: SIMULADOR DE ESCENARIOS - ANÁLISIS DE GAP
A41: DATOS DE ENTRADA | C41: VALOR | E41: RESULTADOS ACTUALES
A42: ESTADO DE CAPTURA | C42: 1753000 | E42: Ingresos Actuales: | F42: =Hoja1!I37
A43: Días capturados: | B43: =COUNTA('Seguimiento Diario'!E6:E36) | C43: de 28 | E43: Tarifa Actual: | F43: =Hoja1!J37
A44: Datos al: | B44: =IF(COUNTA('Seguimiento Diario'!E6:E36)>0, COUNTA('Seguimiento Diario'!E6:E36)&" de "&DAY(TODAY())&" días actuales", "Sin datos") | C44: =Hoja1!B37 | E44: Ocupación Actual: | F44: =Hoja1!H37
A45: Proyección mensual: | B45: =IFERROR(IF(COUNTA('Seguimiento Diario'!E6:E36)>0, "$"&TEXT(ROUND(SUM('Seguimiento Diario'!H6:H36)/COUNTA('Seguimiento Diario'!E6:E36)*'Seguimiento Diario'!$S$6,0),"#,##0"), "-"),"") | C45: =C43-C44 | E45: RevPAR Actual: | F45: =Hoja1!K37
A47: GAP DE INGRESOS | C47: =C42-F42 | E47: % para alcanzar meta: | F47: =IFERROR(C47/F42, "-")
A50: ESCENARIOS PARA ALCANZAR LA META
A52: ESCENARIO | B52: DESCRIPCIÓN | C52: TARIFA NECESARIA | D52: VS ACTUAL | E52: HABITACIONES | F52: VIABILIDAD | G52: CÓMO LOGRARLO
A53: OPCIÓN A | B53: Vender las 303 habs faltantes | C53: =IFERROR(C47/C45, "-") | D53: =IFERROR((C53/F43)-1, "-") | E53: =C43 | F53: ✅ ALTA | G53: Bajar tarifa en días de baja demanda
...

Sheet Seguimiento Diario
A1: SEGUIMIENTO DIARIO - REAL VS META
A2: Propiedad: INH3RI | Meta Mensual: $1,753,000 | Habitaciones: 85 | P2: PROGRESO DEL MES | R2: PERÍODO | T2: NOTA
P3: =COUNTA(E6:E36)&" de "&S6&" días" | Q3: =ROUND(COUNTA(E6:E36)/S6*100,0)&"% completado" | R3: Mes: | S3: 2-Febrero | T3: Los días 29-31 se
A4: RESUMEN ACTUAL | B4: Meta: | D4: 1753000 | E4: Acumulado: | F4: =O33 | G4: Faltante: | H4: =D4-F4 | O4: Días rest: | P4: =REPT("█",ROUND(COUNTA(E6:E36)/S6*10,0))&REPT("░",10-ROUND(COUNTA(E6:E36)/S6*10,0)) | Q4: Tarifa sugerida: | R4: Año: | S4: 2026 | T4: muestran en gris si
A5: DÍA | B5: FECHA | C5: DÍA SEM | D5: OCC EST | E5: OCC REAL | F5: TARIFA EST | G5: TARIFA REAL | H5: INGRESO DÍA | I5: RevPAR EST | J5: RevPAR REAL | K5: % RevPAR | L5: HABS VACÍAS | M5: $ PERDIDO | N5: vs SEM ANT | O5: ACUMULADO | P5: META ACUM | Q5: DIF vs META | R5: Período: | S5: =S3&" "&S4 | T5: no aplican al mes. | U5: TARIFA SUGERIDA | V5: ALERTA TARIFA | W5: PROY. CIERRE | X5: vs META | Y5: HABS EXTRAS vs HOY | Z5: TARIFA SI 100% OCC
A6: 1 | B6: =IF($A6<=$S$6,DATE($S$4,VALUE(LEFT($S$3,FIND("-",$S$3)-1)),$A6),"") | C6: =IF(B6="","",TEXT(B6,"ddd")) | D6: 80 | E6: 69 | F6: 762 | G6: 760 | H6: =IF($A6<=$S$6,IFERROR(E6*G6,0),0) | I6: =F6*(D6/100) | J6: =IF(E6="","",G6*(E6/100)) | K6: =IF(E6="","",J6/I6) | L6: =IF(E6="","",85-E6) | M6: =IF(E6="","",L6*G6) | N6: =IF(OR(E6="",A6<=7),"-",IF(INDEX(H:H,ROW()-7)=0,"-",TEXT((H6-INDEX(H:H,ROW()-7))/ABS(INDEX(H:H,ROW()-7)),"+0%;-0%"))) | O6: =IF($A6<=$S$6,SUM($H$6:H6),0) | P6: =IF($S$6>0,$D$4/$S$6*1,"") | R6: Días del mes: | S6: =DAY(EOMONTH(DATE(S4,VALUE(LEFT(S3,FIND("-",S3)-1)),1),0)) | T6: =IF(E6<>"",D$4-O6,"") | U6: =IF(AND(E6<>"",S6>0),T6/(S6*85),"") | V6: =IF(E6="","",IF(S6=0,"✅ Completado",IF(U6<800,"🟢 Alcanzable",IF(U6<=900,"🟡 Difícil","🔴 Muy difícil")))) | W6: =IF(E6="","",IF(A6=0,"",O6/A6*$S$6)) | X6: =IF(E6="","",W6-$D$4) | Y6: =IF(E6="","",IF(S6=0,"✅ Completado",IF(T6<=0,"✅ Meta alcanzada",ROUNDUP(T6/(S6*G6),0)-E6))) | Z6: =IF(E6="","",IF(S6=0,"-",IF(T6<=0,"-",T6/(S6*85))))
A7: 2 | B7: =IF($A7<=$S$6,DATE($S$4,VALUE(LEFT($S$3,FIND("-",$S$3)-1)),$A7),"") | C7: =IF(B7="","",TEXT(B7,"ddd")) | D7: 76 | E7: 65 | F7: 762 | G7: 750 | H7: =IF($A7<=$S$6,IFERROR(E7*G7,0),0) | I7: =F7*(D7/100) | J7: =IF(E7="","",G7*(E7/100)) | K7: =IF(E7="","",J7/I7) | L7: =IF(E7="","",85-E7) | M7: =IF(E7="","",L7*G7) | N7: =IF(OR(E7="",A7<=7),"-",IF(INDEX(H:H,ROW()-7)=0,"-",TEXT((H7-INDEX(H:H,ROW()-7))/ABS(INDEX(H:H,ROW()-7)),"+0%;-0%"))) | O7: =IF($A7<=$S$6,SUM($H$6:H7),0) | P7: =IF($S$6>0,$D$4/$S$6*2,"") | Q7: =IF(COUNTA(E6:E36)>0, ROUND(SUM(H6:H36)/COUNTA(E6:E36)*S6, 0), 0) | R7: =IF(E7="","",IF(Q7>=0,"🟢",IF(Q7>=-50000,"🟡","🔴"))) | S7: =$S$6-2 | T7: LIMPIAR MES: | U7: =IF(AND(E7<>"",S7>0),T7/(S7*85),"") | V7: =IF(E7="","",IF(S7=0,"✅ Completado",IF(U7<800,"🟢 Alcanzable",IF(U7<=900,"🟡 Difícil","🔴 Muy difícil")))) | W7: =IF(E7="","",IF(A7=0,"",O7/A7*$S$6)) | X7: =IF(E7="","",W7-$D$4) | Y7: =IF(E7="","",IF(S7=0,"✅ Completado",IF(T7<=0,"✅ Meta alcanzada",ROUNDUP(T7/(S7*G7),0)-E7))) | Z7: =IF(E7="","",IF(S7=0,"-",IF(T7<=0,"-",T7/(S7*85))))
A8: 3 | B8: =IF($A8<=$S$6,DATE($S$4,VALUE(LEFT($S$3,FIND("-",$S$3)-1)),$A8),"") | C8: =IF(B8="","",TEXT(B8,"ddd")) | D8: 83 | E8: 68 | F8: 762 | G8: 800 | H8: =IF($A8<=$S$6,IFERROR(E8*G8,0),0) | I8: =F8*(D8/100) | J8: =IF(E8="","",G8*(E8/100)) | K8: =IF(E8="","",J8/I8) | L8: =IF(E8="","",85-E8) | M8: =IF(E8="","",L8*G8) | N8: =IF(OR(E8="",A8<=7),"-",IF(INDEX(H:H,ROW()-7)=0,"-",TEXT((H8-INDEX(H:H,ROW()-7))/ABS(INDEX(H:H,ROW()-7)),"+0%;-0%"))) | O8: =IF($A8<=$S$6,SUM($H$6:H8),0) | P8: =IF($S$6>0,$D$4/$S$6*3,"") | Q8: =IF(COUNTA(E6:E36)>0, ROUND(AVERAGE(E6:E36), 1)&"%", "-") | R8: =IF(E8="","",IF(Q8>=0,"🟢",IF(Q8>=-50000,"🟡","🔴"))) | S8: =$S$6-3 | T8: Para nuevo mes: | U8: =IF(AND(E8<>"",S8>0),T8/(S8*85),"") | V8: =IF(E8="","",IF(S8=0,"✅ Completado",IF(U8<800,"🟢 Alcanzable",IF(U8<=900,"🟡 Difícil","🔴 Muy difícil")))) | W8: =IF(E8="","",IF(A8=0,"",O8/A8*$S$6)) | X8: =IF(E8="","",W8-$D$4) | Y8: =IF(E8="","",IF(S8=0,"✅ Completado",IF(T8<=0,"✅ Meta alcanzada",ROUNDUP(T8/(S8*G8),0)-E8))) | Z8: =IF(E8="","",IF(S8=0,"-",IF(T8<=0,"-",T8/(S8*85))))
A9: 4 | B9: =IF($A9<=$S$6,DATE($S$4,VALUE(LEFT($S$3,FIND("-",$S$3)-1)),$A9),"") | C9: =IF(B9="","",TEXT(B9,"ddd")) | D9: 83 | E9: 40 | F9: 762 | G9: 700 | H9: =IF($A9<=$S$6,IFERROR(E9*G9,0),0) | I9: =F9*(D9/100) | J9: =IF(E9="","",G9*(E9/100)) | K9: =IF(E9="","",J9/I9) | L9: =IF(E9="","",85-E9) | M9: =IF(E9="","",L9*G9) | N9: =IF(OR(E9="",A9<=7),"-",IF(INDEX(H:H,ROW()-7)=0,"-",TEXT((H9-INDEX(H:H,ROW()-7))/ABS(INDEX(H:H,ROW()-7)),"+0%;-0%"))) | O9: =IF($A9<=$S$6,SUM($H$6:H9),0) | P9: =IF($S$6>0,$D$4/$S$6*4,"") | Q9: =IF(COUNTA(E6:E36)>0, ROUND(AVERAGEIF(J6:J36,"<>0"), 0), 0) | R9: =IF(E9="","",IF(Q9>=0,"🟢",IF(Q9>=-50000,"🟡","🔴"))) | S9: =$S$6-4 | T9: 1. Cambiar S3 (mes) | U9: =IF(AND(E9<>"",S9>0),T9/(S9*85),"") | V9: =IF(E9="","",IF(S9=0,"✅ Completado",IF(U9<800,"🟢 Alcanzable",IF(U9<=900,"🟡 Difícil","🔴 Muy difícil")))) | W9: =IF(E9="","",IF(A9=0,"",O9/A9*$S$6)) | X9: =IF(E9="","",W9-$D$4) | Y9: =IF(E9="","",IF(S9=0,"✅ Completado",IF(T9<=0,"✅ Meta alcanzada",ROUNDUP(T9/(S9*G9),0)-E9))) | Z9: =IF(E9="","",IF(S9=0,"-",IF(T9<=0,"-",T9/(S9*85))))
A10: 5 | B10: =IF($A10<=$S$6,DATE($S$4,VALUE(LEFT($S$3,FIND("-",$S$3)-1)),$A10),"") | C10: =IF(B10="","",TEXT(B10,"ddd")) | D10: 85 | E10: 85 | F10: 762 | G10: 780 | H10: =IF($A10<=$S$6,IFERROR(E10*G10,0),0) | I10: =F10*(D10/100) | J10: =IF(E10="","",G10*(E10/100)) | K10: =IF(E10="","",J10/I10) | L10: =IF(E10="","",85-E10) | M10: =IF(E10="","",L10*G10) | N10: =IF(OR(E10="",A10<=7),"-",IF(INDEX(H:H,ROW()-7)=0,"-",TEXT((H10-INDEX(H:H,ROW()-7))/ABS(INDEX(H:H,ROW()-7)),"+0%;-0%"))) | O10: =IF($A10<=$S$6,SUM($H$6:H10),0) | P10: =IF($S$6>0,$D$4/$S$6*5,"") | Q10: =IF(COUNTA(E6:E36)>0, IF(Q7>=D4, "✓ En meta", "⚠ "&ROUND((1-Q7/D4)*100,0)&"% bajo"), "-") | R10: =IF(E10="","",IF(Q10>=0,"🟢",IF(Q10>=-50000,"🟡","🔴"))) | S10: =$S$6-5 | T10: 2. Borrar E6:E36 | U10: =IF(AND(E10<>"",S10>0),T10/(S10*85),"") | V10: =IF(E10="","",IF(S10=0,"✅ Completado",IF(U10<800,"🟢 Alcanzable",IF(U10<=900,"🟡 Difícil","🔴 Muy difícil")))) | W10: =IF(E10="","",IF(A10=0,"",O10/A10*$S$6)) | X10: =IF(E10="","",W10-$D$4) | Y10: =IF(E10="","",IF(S10=0,"✅ Completado",IF(T10<=0,"✅ Meta alcanzada",ROUNDUP(T10/(S10*G10),0)-E10))) | Z10: =IF(E10="","",IF(S10=0,"-",IF(T10<=0,"-",T10/(S10*85))))
A11: 6 | B11: =IF($A11<=$S$6,DATE($S$4,VALUE(LEFT($S$3,FIND("-",$S$3)-1)),$A11),"") | C11: =IF(B11="","",TEXT(B11,"ddd")) | D11: 85 | E11: 80 | F11: 762 | G11: 800 | H11: =IF($A11<=$S$6,IFERROR(E11*G11,0),0) | I11: =F11*(D11/100) | J11: =IF(E11="","",G11*(E11/100)) | K11: =IF(E11="","",J11/I11) | L11: =IF(E11="","",85-E11) | M11: =IF(E11="","",L11*G11) | N11: =IF(OR(E11="",A11<=7),"-",IF(INDEX(H:H,ROW()-7)=0,"-",TEXT((H11-INDEX(H:H,ROW()-7))/ABS(INDEX(H:H,ROW()-7)),"+0%;-0%"))) | O11: =IF($A11<=$S$6,SUM($H$6:H11),0) | P11: =IF($S$6>0,$D$4/$S$6*6,"") | R11: =IF(E11="","",IF(Q11>=0,"🟢",IF(Q11>=-50000,"🟡","🔴"))) | S11: =$S$6-6 | T11: 3. Borrar G6:G36 | U11: =IF(AND(E11<>"",S11>0),T11/(S11*85),"") | V11: =IF(E11="","",IF(S11=0,"✅ Completado",IF(U11<800,"🟢 Alcanzable",IF(U11<=900,"🟡 Difícil","🔴 Muy difícil")))) | W11: =IF(E11="","",IF(A11=0,"",O11/A11*$S$6)) | X11: =IF(E11="","",W11-$D$4) | Y11: =IF(E11="","",IF(S11=0,"✅ Completado",IF(T11<=0,"✅ Meta alcanzada",ROUNDUP(T11/(S11*G11),0)-E11))) | Z11: =IF(E11="","",IF(S11=0,"-",IF(T11<=0,"-",T11/(S11*85))))
A12: 7 | B12: =IF($A12<=$S$6,DATE($S$4,VALUE(LEFT($S$3,FIND("-",$S$3)-1)),$A12),"") | C12: =IF(B12="","",TEXT(B12,"ddd")) | D12: 85 | E12: 85 | F12: 762 | G12: 780 | H12: =IF($A12<=$S$6,IFERROR(E12*G12,0),0) | I12: =F12*(D12/100) | J12: =IF(E12="","",G12*(E12/100)) | K12: =IF(E12="","",J12/I12) | L12: =IF(E12="","",85-E12) | M12: =IF(E12="","",L12*G12) | N12: =IF(OR(E12="",A12<=7),"-",IF(INDEX(H:H,ROW()-7)=0,"-",TEXT((H12-INDEX(H:H,ROW()-7))/ABS(INDEX(H:H,ROW()-7)),"+0%;-0%"))) | O12: =IF($A12<=$S$6,SUM($H$6:H12),0) | P12: =IF($S$6>0,$D$4/$S$6*7,"") | R12: =IF(E12="","",IF(Q12>=0,"🟢",IF(Q12>=-50000,"🟡","🔴"))) | S12: =$S$6-7 | T12: (O usar filtro y | U12: =IF(AND(E12<>"",S12>0),T12/(S12*85),"") | V12: =IF(E12="","",IF(S12=0,"✅ Completado",IF(U12<800,"🟢 Alcanzable",IF(U12<=900,"🟡 Difícil","🔴 Muy difícil")))) | W12: =IF(E12="","",IF(A12=0,"",O12/A12*$S$6)) | X12: =IF(E12="","",W12-$D$4) | Y12: =IF(E12="","",IF(S12=0,"✅ Completado",IF(T12<=0,"✅ Meta alcanzada",ROUNDUP(T12/(S12*G12),0)-E12))) | Z12: =IF(E12="","",IF(S12=0,"-",IF(T12<=0,"-",T12/(S12*85))))
A13: 8 | B13: =IF($A13<=$S$6,DATE($S$4,VALUE(LEFT($S$3,FIND("-",$S$3)-1)),$A13),"") | C13: =IF(B13="","",TEXT(B13,"ddd")) | D13: 83 | E13: 70 | F13: 762 | G13: 780 | H13: =IF($A13<=$S$6,IFERROR(E13*G13,0),0) | I13: =F13*(D13/100) | J13: =IF(E13="","",G13*(E13/100)) | K13: =IF(E13="","",J13/I13) | L13: =IF(E13="","",85-E13) | M13: =IF(E13="","",L13*G13) | N13: =IF(OR(E13="",A13<=7),"-",IF(INDEX(H:H,ROW()-7)=0,"-",TEXT((H13-INDEX(H:H,ROW()-7))/ABS(INDEX(H:H,ROW()-7)),"+0%;-0%"))) | O13: =IF($A13<=$S$6,SUM($H$6:H13),0) | P13: =IF($S$6>0,$D$4/$S$6*8,"") | R13: =IF(E13="","",IF(Q13>=0,"🟢",IF(Q13>=-50000,"🟡","🔴"))) | S13: =$S$6-8 | T13: borrar valores) | U13: =IF(AND(E13<>"",S13>0),T13/(S13*85),"") | V13: =IF(E13="","",IF(S13=0,"✅ Completado",IF(U13<800,"🟢 Alcanzable",IF(U13<=900,"🟡 Difícil","🔴 Muy difícil")))) | W13: =IF(E13="","",IF(A13=0,"",O13/A13*$S$6)) | X13: =IF(E13="","",W13-$D$4) | Y13: =IF(E13="","",IF(S13=0,"✅ Completado",IF(T13<=0,"✅ Meta alcanzada",ROUNDUP(T13/(S13*G13),0)-E13))) | Z13: =IF(E13="","",IF(S13=0,"-",IF(T13<=0,"-",T13/(S13*85))))
A14: 9 | B14: =IF($A14<=$S$6,DATE($S$4,VALUE(LEFT($S$3,FIND("-",$S$3)-1)),$A14),"") | C14: =IF(B14="","",TEXT(B14,"ddd")) | D14: 85 | E14: 82 | F14: 762 | G14: 780 | H14: =IF($A14<=$S$6,IFERROR(E14*G14,0),0) | I14: =F14*(D14/100) | J14: =IF(E14="","",G14*(E14/100)) | K14: =IF(E14="","",J14/I14) | L14: =IF(E14="","",85-E14) | M14: =IF(E14="","",L14*G14) | N14: =IF(OR(E14="",A14<=7),"-",IF(INDEX(H:H,ROW()-7)=0,"-",TEXT((H14-INDEX(H:H,ROW()-7))/ABS(INDEX(H:H,ROW()-7)),"+0%;-0%"))) | O14: =IF($A14<=$S$6,SUM($H$6:H14),0) | P14: =IF($S$6>0,$D$4/$S$6*9,"") | R14: =IF(E14="","",IF(Q14>=0,"🟢",IF(Q14>=-50000,"🟡","🔴"))) | S14: =$S$6-9 | T14: =IF(E14<>"",D$4-O14,"") | U14: =IF(AND(E14<>"",S14>0),T14/(S14*85),"") | V14: =IF(E14="","",IF(S14=0,"✅ Completado",IF(U14<800,"🟢 Alcanzable",IF(U14<=900,"🟡 Difícil","🔴 Muy difícil")))) | W14: =IF(E14="","",IF(A14=0,"",O14/A14*$S$6)) | X14: =IF(E14="","",W14-$D$4) | Y14: =IF(E14="","",IF(S14=0,"✅ Completado",IF(T14<=0,"✅ Meta alcanzada",ROUNDUP(T14/(S14*G14),0)-E14))) | Z14: =IF(E14="","",IF(S14=0,"-",IF(T14<=0,"-",T14/(S14*85))))
A15: 10 | B15: =IF($A15<=$S$6,DATE($S$4,VALUE(LEFT($S$3,FIND("-",$S$3)-1)),$A15),"") | C15: =IF(B15="","",TEXT(B15,"ddd")) | D15: 85 | E15: 80 | F15: 762 | G15: 800 | H15: =IF($A15<=$S$6,IFERROR(E15*G15,0),0) | I15: =F15*(D15/100) | J15: =IF(E15="","",G15*(E15/100)) | K15: =IF(E15="","",J15/I15) | L15: =IF(E15="","",85-E15) | M15: =IF(E15="","",L15*G15) | N15: =IF(OR(E15="",A15<=7),"-",IF(INDEX(H:H,ROW()-7)=0,"-",TEXT((H15-INDEX(H:H,ROW()-7))/ABS(INDEX(H:H,ROW()-7)),"+0%;-0%"))) | O15: =IF($A15<=$S$6,SUM($H$6:H15),0) | P15: =IF($S$6>0,$D$4/$S$6*10,"") | Q15: =O15-P15 | R15: =IF(E15="","",IF(Q15>=0,"🟢",IF(Q15>=-50000,"🟡","🔴"))) | S15: =$S$6-10 | T15: =IF(E15<>"",D$4-O15,"") | U15: =IF(AND(E15<>"",S15>0),T15/(S15*85),"") | V15: =IF(E15="","",IF(S15=0,"✅ Completado",IF(U15<800,"🟢 Alcanzable",IF(U15<=900,"🟡 Difícil","🔴 Muy difícil")))) | W15: =IF(E15="","",IF(A15=0,"",O15/A15*$S$6)) | X15: =IF(E15="","",W15-$D$4) | Y15: =IF(E15="","",IF(S15=0,"✅ Completado",IF(T15<=0,"✅ Meta alcanzada",ROUNDUP(T15/(S15*G15),0)-E15))) | Z15: =IF(E15="","",IF(S15=0,"-",IF(T15<=0,"-",T15/(S15*85))))
A16: 11 | B16: =IF($A16<=$S$6,DATE($S$4,VALUE(LEFT($S$3,FIND("-",$S$3)-1)),$A16),"") | C16: =IF(B16="","",TEXT(B16,"ddd")) | D16: 85 | E16: 75 | F16: 762 | G16: 720 | H16: =IF($A16<=$S$6,IFERROR(E16*G16,0),0) | I16: =F16*(D16/100) | J16: =IF(E16="","",G16*(E16/100)) | K16: =IF(E16="","",J16/I16) | L16: =IF(E16="","",85-E16) | M16: =IF(E16="","",L16*G16) | N16: =IF(OR(E16="",A16<=7),"-",IF(INDEX(H:H,ROW()-7)=0,"-",TEXT((H16-INDEX(H:H,ROW()-7))/ABS(INDEX(H:H,ROW()-7)),"+0%;-0%"))) | O16: =IF($A16<=$S$6,SUM($H$6:H16),0) | P16: =IF($S$6>0,$D$4/$S$6*11,"") | Q16: =O16-P16 | R16: =IF(E16="","",IF(Q16>=0,"🟢",IF(Q16>=-50000,"🟡","🔴"))) | S16: =$S$6-11 | T16: =IF(E16<>"",D$4-O16,"") | U16: =IF(AND(E16<>"",S16>0),T16/(S16*85),"") | V16: =IF(E16="","",IF(S16=0,"✅ Completado",IF(U16<800,"🟢 Alcanzable",IF(U16<=900,"🟡 Difícil","🔴 Muy difícil")))) | W16: =IF(E16="","",IF(A16=0,"",O16/A16*$S$6)) | X16: =IF(E16="","",W16-$D$4) | Y16: =IF(E16="","",IF(S16=0,"✅ Completado",IF(T16<=0,"✅ Meta alcanzada",ROUNDUP(T16/(S16*G16),0)-E16))) | Z16: =IF(E16="","",IF(S16=0,"-",IF(T16<=0,"-",T16/(S16*85))))
A17: 12 | B17: =IF($A17<=$S$6,DATE($S$4,VALUE(LEFT($S$3,FIND("-",$S$3)-1)),$A17),"") | C17: =IF(B17="","",TEXT(B17,"ddd")) | D17: 85 | E17: 88 | F17: 762 | G17: 790 | H17: =IF($A17<=$S$6,IFERROR(E17*G17,0),0) | I17: =F17*(D17/100) | J17: =IF(E17="","",G17*(E17/100)) | K17: =IF(E17="","",J17/I17) | L17: =IF(E17="","",85-E17) | M17: =IF(E17="","",L17*G17) | N17: =IF(OR(E17="",A17<=7),"-",IF(INDEX(H:H,ROW()-7)=0,"-",TEXT((H17-INDEX(H:H,ROW()-7))/ABS(INDEX(H:H,ROW()-7)),"+0%;-0%"))) | O17: =IF($A17<=$S$6,SUM($H$6:H17),0) | P17: =IF($S$6>0,$D$4/$S$6*12,"") | Q17: =O17-P17 | R17: =IF(E17="","",IF(Q17>=0,"🟢",IF(Q17>=-50000,"🟡","🔴"))) | S17: =$S$6-12 | T17: =IF(E17<>"",D$4-O17,"") | U17: =IF(AND(E17<>"",S17>0),T17/(S17*85),"") | V17: =IF(E17="","",IF(S17=0,"✅ Completado",IF(U17<800,"🟢 Alcanzable",IF(U17<=900,"🟡 Difícil","🔴 Muy difícil")))) | W17: =IF(E17="","",IF(A17=0,"",O17/A17*$S$6)) | X17: =IF(E17="","",W17-$D$4) | Y17: =IF(E17="","",IF(S17=0,"✅ Completado",IF(T17<=0,"✅ Meta alcanzada",ROUNDUP(T17/(S17*G17),0)-E17))) | Z17: =IF(E17="","",IF(S17=0,"-",IF(T17<=0,"-",T17/(S17*85))))
A18: 13 | B18: =IF($A18<=$S$6,DATE($S$4,VALUE(LEFT($S$3,FIND("-",$S$3)-1)),$A18),"") | C18: =IF(B18="","",TEXT(B18,"ddd")) | D18: 85 | E18: 82 | F18: 762 | G18: 820 | H18: =IF($A18<=$S$6,IFERROR(E18*G18,0),0) | I18: =F18*(D18/100) | J18: =IF(E18="","",G18*(E18/100)) | K18: =IF(E18="","",J18/I18) | L18: =IF(E18="","",85-E18) | M18: =IF(E18="","",L18*G18) | N18: =IF(OR(E18="",A18<=7),"-",IF(INDEX(H:H,ROW()-7)=0,"-",TEXT((H18-INDEX(H:H,ROW()-7))/ABS(INDEX(H:H,ROW()-7)),"+0%;-0%"))) | O18: =IF($A18<=$S$6,SUM($H$6:H18),0) | P18: =IF($S$6>0,$D$4/$S$6*13,"") | Q18: =O18-P18 | R18: =IF(E18="","",IF(Q18>=0,"🟢",IF(Q18>=-50000,"🟡","🔴"))) | S18: =$S$6-13 | T18: =IF(E18<>"",D$4-O18,"") | U18: =IF(AND(E18<>"",S18>0),T18/(S18*85),"") | V18: =IF(E18="","",IF(S18=0,"✅ Completado",IF(U18<800,"🟢 Alcanzable",IF(U18<=900,"🟡 Difícil","🔴 Muy difícil")))) | W18: =IF(E18="","",IF(A18=0,"",O18/A18*$S$6)) | X18: =IF(E18="","",W18-$D$4) | Y18: =IF(E18="","",IF(S18=0,"✅ Completado",IF(T18<=0,"✅ Meta alcanzada",ROUNDUP(T18/(S18*G18),0)-E18))) | Z18: =IF(E18="","",IF(S18=0,"-",IF(T18<=0,"-",T18/(S18*85))))
A19: 14 | B19: =IF($A19<=$S$6,DATE($S$4,VALUE(LEFT($S$3,FIND("-",$S$3)-1)),$A19),"") | C19: =IF(B19="","",TEXT(B19,"ddd")) | D19: 85 | E19: 85 | F19: 762 | G19: 850 | H19: =IF($A19<=$S$6,IFERROR(E19*G19,0),0) | I19: =F19*(D19/100) | J19: =IF(E19="","",G19*(E19/100)) | K19: =IF(E19="","",J19/I19) | L19: =IF(E19="","",85-E19) | M19: =IF(E19="","",L19*G19) | N19: =IF(OR(E19="",A19<=7),"-",IF(INDEX(H:H,ROW()-7)=0,"-",TEXT((H19-INDEX(H:H,ROW()-7))/ABS(INDEX(H:H,ROW()-7)),"+0%;-0%"))) | O19: =IF($A19<=$S$6,SUM($H$6:H19),0) | P19: =IF($S$6>0,$D$4/$S$6*14,"") | Q19: =O19-P19 | R19: =IF(E19="","",IF(Q19>=0,"🟢",IF(Q19>=-50000,"🟡","🔴"))) | S19: =$S$6-14 | T19: =IF(E19<>"",D$4-O19,"") | U19: =IF(AND(E19<>"",S19>0),T19/(S19*85),"") | V19: =IF(E19="","",IF(S19=0,"✅ Completado",IF(U19<800,"🟢 Alcanzable",IF(U19<=900,"🟡 Difícil","🔴 Muy difícil")))) | W19: =IF(E19="","",IF(A19=0,"",O19/A19*$S$6)) | X19: =IF(E19="","",W19-$D$4) | Y19: =IF(E19="","",IF(S19=0,"✅ Completado",IF(T19<=0,"✅ Meta alcanzada",ROUNDUP(T19/(S19*G19),0)-E19))) | Z19: =IF(E19="","",IF(S19=0,"-",IF(T19<=0,"-",T19/(S19*85))))
A20: 15 | B20: =IF($A20<=$S$6,DATE($S$4,VALUE(LEFT($S$3,FIND("-",$S$3)-1)),$A20),"") | C20: =IF(B20="","",TEXT(B20,"ddd")) | D20: 78 | E20: 72 | F20: 762 | G20: 760 | H20: =IF($A20<=$S$6,IFERROR(E20*G20,0),0) | I20: =F20*(D20/100) | J20: =IF(E20="","",G20*(E20/100)) | K20: =IF(E20="","",J20/I20) | L20: =IF(E20="","",85-E20) | M20: =IF(E20="","",L20*G20) | N20: =IF(OR(E20="",A20<=7),"-",IF(INDEX(H:H,ROW()-7)=0,"-",TEXT((H20-INDEX(H:H,ROW()-7))/ABS(INDEX(H:H,ROW()-7)),"+0%;-0%"))) | O20: =IF($A20<=$S$6,SUM($H$6:H20),0) | P20: =IF($S$6>0,$D$4/$S$6*15,"") | Q20: =O20-P20 | R20: =IF(E20="","",IF(Q20>=0,"🟢",IF(Q20>=-50000,"🟡","🔴"))) | S20: =$S$6-15 | T20: =IF(E20<>"",D$4-O20,"") | U20: =IF(AND(E20<>"",S20>0),T20/(S20*85),"") | V20: =IF(E20="","",IF(S20=0,"✅ Completado",IF(U20<800,"🟢 Alcanzable",IF(U20<=900,"🟡 Difícil","🔴 Muy difícil")))) | W20: =IF(E20="","",IF(A20=0,"",O20/A20*$S$6)) | X20: =IF(E20="","",W20-$D$4) | Y20: =IF(E20="","",IF(S20=0,"✅ Completado",IF(T20<=0,"✅ Meta alcanzada",ROUNDUP(T20/(S20*G20),0)-E20))) | Z20: =IF(E20="","",IF(S20=0,"-",IF(T20<=0,"-",T20/(S20*85))))
A21: 16 | B21: =IF($A21<=$S$6,DATE($S$4,VALUE(LEFT($S$3,FIND("-",$S$3)-1)),$A21),"") | C21: =IF(B21="","",TEXT(B21,"ddd")) | D21: 78 | E21: 80 | F21: 762 | G21: 780 | H21: =IF($A21<=$S$6,IFERROR(E21*G21,0),0) | I21: =F21*(D21/100) | J21: =IF(E21="","",G21*(E21/100)) | K21: =IF(E21="","",J21/I21) | L21: =IF(E21="","",85-E21) | M21: =IF(E21="","",L21*G21) | N21: =IF(OR(E21="",A21<=7),"-",IF(INDEX(H:H,ROW()-7)=0,"-",TEXT((H21-INDEX(H:H,ROW()-7))/ABS(INDEX(H:H,ROW()-7)),"+0%;-0%"))) | O21: =IF($A21<=$S$6,SUM($H$6:H21),0) | P21: =IF($S$6>0,$D$4/$S$6*16,"") | Q21: =O21-P21 | R21: =IF(E21="","",IF(Q21>=0,"🟢",IF(Q21>=-50000,"🟡","🔴"))) | S21: =$S$6-16 | T21: =IF(E21<>"",D$4-O21,"") | U21: =IF(AND(E21<>"",S21>0),T21/(S21*85),"") | V21: =IF(E21="","",IF(S21=0,"✅ Completado",IF(U21<800,"🟢 Alcanzable",IF(U21<=900,"🟡 Difícil","🔴 Muy difícil")))) | W21: =IF(E21="","",IF(A21=0,"",O21/A21*$S$6)) | X21: =IF(E21="","",W21-$D$4) | Y21: =IF(E21="","",IF(S21=0,"✅ Completado",IF(T21<=0,"✅ Meta alcanzada",ROUNDUP(T21/(S21*G21),0)-E21))) | Z21: =IF(E21="","",IF(S21=0,"-",IF(T21<=0,"-",T21/(S21*85))))
